<?xml version="1.0" ?>
<!-- =================================================================================== -->
<!-- |    This document was autogenerated by xacro from robot.urdf.xacro               | -->
<!-- |    EDITING THIS FILE BY HAND IS NOT RECOMMENDED                                 | -->
<!-- =================================================================================== -->
<robot name="four_wheel_robot">
  <!-- 材料定义 Materials -->
  <material name="chassis_material">
    <color rgba="0.2 0.2 0.8 1.0"/>
  </material>
  <material name="wheel_material">
    <color rgba="0.1 0.1 0.1 1.0"/>
  </material>
  <!-- 虚拟的base_footprint链接 -->
  <link name="base_footprint">
    </link>
  <!-- 机器人底盘 Base Link -->
  <link name="base_link">
    <visual>
      <origin rpy="0 0 0" xyz="0 0 0"/>
      <geometry>
        <box size="0.6 0.4 0.1"/>
      </geometry>
      <material name="chassis_material"/>
    </visual>
    <collision>
      <origin rpy="0 0 0" xyz="0 0 0"/>
      <geometry>
        <box size="0.6 0.4 0.1"/>
      </geometry>
    </collision>
    <inertial>
      <origin rpy="0 0 0" xyz="0 0 0"/>
      <mass value="10.0"/>
      <inertia ixx="0.1416666666666667" ixy="0" ixz="0" iyy="0.30833333333333335" iyz="0" izz="0.43333333333333335"/>
    </inertial>
  </link>
  <!-- base_footprint到base_link的关节 -->
  <joint name="base_footprint_joint" type="fixed">
    <parent link="base_footprint"/>
    <child link="base_link"/>
    <origin rpy="0 0 0" xyz="0 0 0.13"/>
  </joint>
  <link name="rear_left_wheel">
    <visual>
      <origin rpy="1.5708 0 0" xyz="0 0 0"/>
      <geometry>
        <cylinder length="0.06" radius="0.08"/>
      </geometry>
      <material name="wheel_material"/>
    </visual>
    <collision>
      <origin rpy="1.5708 0 0" xyz="0 0 0"/>
      <geometry>
        <cylinder length="0.06" radius="0.08"/>
      </geometry>
    </collision>
    <inertial>
      <origin rpy="1.5708 0 0" xyz="0 0 0"/>
      <mass value="1.0"/>
      <inertia ixx="0.003" ixy="0" ixz="0" iyy="0.003" iyz="0" izz="0.005"/>
    </inertial>
  </link>
  <joint name="rear_left_wheel_joint" type="continuous">
    <parent link="base_link"/>
    <child link="rear_left_wheel"/>
    <origin rpy="0 0 0" xyz="-0.2 0.23 -0.05"/>
    <axis xyz="0 1 0"/>
    <dynamics damping="0.1" friction="0.1"/>
  </joint>
  <link name="rear_right_wheel">
    <visual>
      <origin rpy="1.5708 0 0" xyz="0 0 0"/>
      <geometry>
        <cylinder length="0.06" radius="0.08"/>
      </geometry>
      <material name="wheel_material"/>
    </visual>
    <collision>
      <origin rpy="1.5708 0 0" xyz="0 0 0"/>
      <geometry>
        <cylinder length="0.06" radius="0.08"/>
      </geometry>
    </collision>
    <inertial>
      <origin rpy="1.5708 0 0" xyz="0 0 0"/>
      <mass value="1.0"/>
      <inertia ixx="0.003" ixy="0" ixz="0" iyy="0.003" iyz="0" izz="0.005"/>
    </inertial>
  </link>
  <joint name="rear_right_wheel_joint" type="continuous">
    <parent link="base_link"/>
    <child link="rear_right_wheel"/>
    <origin rpy="0 0 0" xyz="-0.2 -0.23 -0.05"/>
    <axis xyz="0 1 0"/>
    <dynamics damping="0.1" friction="0.1"/>
  </joint>
  <!-- 使用球形万向轮 -->
  <link name="front_left_caster_wheel">
    <visual>
      <origin rpy="0 0 0" xyz="0 0 0"/>
      <geometry>
        <sphere radius="0.04"/>
      </geometry>
      <material name="wheel_material"/>
    </visual>
    <collision>
      <origin rpy="0 0 0" xyz="0 0 0"/>
      <geometry>
        <sphere radius="0.04"/>
      </geometry>
      <surface>
        <friction>
          <ode>
            <mu>0.01</mu>
            <mu2>0.01</mu2>
          </ode>
        </friction>
      </surface>
    </collision>
    <inertial>
      <origin rpy="0 0 0" xyz="0 0 0"/>
      <mass value="0.5"/>
      <inertia ixx="0.00032" ixy="0" ixz="0" iyy="0.00032" iyz="0" izz="0.00032"/>
    </inertial>
  </link>
  <joint name="front_left_caster_joint" type="fixed">
    <parent link="base_link"/>
    <child link="front_left_caster_wheel"/>
    <!-- 调整高度以匹配后轮接触地面 -->
    <origin rpy="0 0 0" xyz="0.2 0.23 -0.09"/>
  </joint>
  <!-- Gazebo配置 -->
  <gazebo reference="front_left_caster_wheel">
    <material>Gazebo/Black</material>
    <mu1>0.01</mu1>
    <mu2>0.01</mu2>
    <kp>1000000.0</kp>
    <kd>100.0</kd>
    <minDepth>0.001</minDepth>
    <maxVel>1.0</maxVel>
  </gazebo>
  <!-- 使用球形万向轮 -->
  <link name="front_right_caster_wheel">
    <visual>
      <origin rpy="0 0 0" xyz="0 0 0"/>
      <geometry>
        <sphere radius="0.04"/>
      </geometry>
      <material name="wheel_material"/>
    </visual>
    <collision>
      <origin rpy="0 0 0" xyz="0 0 0"/>
      <geometry>
        <sphere radius="0.04"/>
      </geometry>
      <surface>
        <friction>
          <ode>
            <mu>0.01</mu>
            <mu2>0.01</mu2>
          </ode>
        </friction>
      </surface>
    </collision>
    <inertial>
      <origin rpy="0 0 0" xyz="0 0 0"/>
      <mass value="0.5"/>
      <inertia ixx="0.00032" ixy="0" ixz="0" iyy="0.00032" iyz="0" izz="0.00032"/>
    </inertial>
  </link>
  <joint name="front_right_caster_joint" type="fixed">
    <parent link="base_link"/>
    <child link="front_right_caster_wheel"/>
    <!-- 调整高度以匹配后轮接触地面 -->
    <origin rpy="0 0 0" xyz="0.2 -0.23 -0.09"/>
  </joint>
  <!-- Gazebo配置 -->
  <gazebo reference="front_right_caster_wheel">
    <material>Gazebo/Black</material>
    <mu1>0.01</mu1>
    <mu2>0.01</mu2>
    <kp>1000000.0</kp>
    <kd>100.0</kd>
    <minDepth>0.001</minDepth>
    <maxVel>1.0</maxVel>
  </gazebo>
  <!-- 激光雷达材料 Lidar Material -->
  <material name="lidar_material">
    <color rgba="0.8 0.2 0.2 1.0"/>
  </material>
  <!-- 摄像头材料 Camera Material -->
  <material name="camera_material">
    <color rgba="0.2 0.8 0.2 1.0"/>
  </material>
  <!-- IMU材料 IMU Material -->
  <material name="imu_material">
    <color rgba="0.8 0.8 0.2 1.0"/>
  </material>
  <link name="lidar_link">
    <visual>
      <origin rpy="0 0 0" xyz="0 0 0"/>
      <geometry>
        <cylinder length="0.08" radius="0.05"/>
      </geometry>
      <material name="lidar_material"/>
    </visual>
    <collision>
      <origin rpy="0 0 0" xyz="0 0 0"/>
      <geometry>
        <cylinder length="0.08" radius="0.05"/>
      </geometry>
    </collision>
    <inertial>
      <origin rpy="0 0 0" xyz="0 0 0"/>
      <mass value="0.5"/>
      <inertia ixx="0.0005791666666666667" ixy="0" ixz="0" iyy="0.0005791666666666667" iyz="0" izz="0.0006250000000000001"/>
    </inertial>
  </link>
  <!-- 激光雷达关节 Lidar Joint - 位于车子中央上方 -->
  <joint name="lidar_joint" type="fixed">
    <parent link="base_link"/>
    <child link="lidar_link"/>
    <!-- 修正：相对于base_link中心，向上偏移半个chassis高度和半个lidar高度 -->
    <origin rpy="0 0 0" xyz="0 0 0.09999999999999999"/>
  </joint>
  <!-- Gazebo 激光雷达插件 -->
  <gazebo reference="lidar_link">
    <sensor name="lidar_sensor" type="ray">
      <pose>0 0 0 0 0 0</pose>
      <visualize>true</visualize>
      <update_rate>40</update_rate>
      <ray>
        <scan>
          <horizontal>
            <samples>720</samples>
            <resolution>1</resolution>
            <min_angle>-3.14159</min_angle>
            <max_angle>3.14159</max_angle>
          </horizontal>
        </scan>
        <range>
          <min>0.12</min>
          <max>30.0</max>
          <resolution>0.015</resolution>
        </range>
        <noise>
          <type>gaussian</type>
          <mean>0.0</mean>
          <stddev>0.01</stddev>
        </noise>
      </ray>
      <plugin filename="libgazebo_ros_ray_sensor.so" name="gazebo_ros_lidar_controller">
        <ros>
          <namespace>/robot</namespace>
          <!-- 使用新的remap语法 -->
          <remapping>~/out:=/robot/scan</remapping>
        </ros>
        <output_type>sensor_msgs/LaserScan</output_type>
        <frame_name>lidar_link</frame_name>
      </plugin>
    </sensor>
  </gazebo>
  <link name="camera_link">
    <visual>
      <origin rpy="0 0 0" xyz="0 0 0"/>
      <geometry>
        <box size="0.08 0.06 0.04"/>
      </geometry>
      <material name="camera_material"/>
    </visual>
    <collision>
      <origin rpy="0 0 0" xyz="0 0 0"/>
      <geometry>
        <box size="0.08 0.06 0.04"/>
      </geometry>
    </collision>
    <inertial>
      <origin rpy="0 0 0" xyz="0 0 0"/>
      <mass value="0.3"/>
      <inertia ixx="0.00013" ixy="0" ixz="0" iyy="0.00019999999999999998" iyz="0" izz="0.00025"/>
    </inertial>
  </link>
  <!-- 摄像头关节 Camera Joint - 位于车子前方 -->
  <joint name="camera_joint" type="fixed">
    <parent link="base_link"/>
    <child link="camera_link"/>
    <!-- 修正：base_link的中心在chassis_height/2的位置，所以相机只需要在此基础上偏移 -->
    <origin rpy="0 0 0" xyz="0.36 0 0.09000000000000001"/>
  </joint>
  <!-- 摄像头光学框架 Camera Optical Frame -->
  <link name="camera_optical_link">
        </link>
  <joint name="camera_optical_joint" type="fixed">
    <parent link="camera_link"/>
    <child link="camera_optical_link"/>
    <origin rpy="-1.5708 0 -1.5708" xyz="0 0 0"/>
  </joint>
  <!-- Gazebo 摄像头插件 -->
  <gazebo reference="camera_link">
    <sensor name="camera_sensor" type="camera">
      <update_rate>30.0</update_rate>
      <camera name="head">
        <horizontal_fov>1.3962634</horizontal_fov>
        <image>
          <width>800</width>
          <height>600</height>
          <format>R8G8B8</format>
        </image>
        <clip>
          <near>0.02</near>
          <far>300</far>
        </clip>
        <noise>
          <type>gaussian</type>
          <mean>0.0</mean>
          <stddev>0.007</stddev>
        </noise>
      </camera>
      <plugin filename="libgazebo_ros_camera.so" name="camera_controller">
        <ros>
          <namespace>/robot</namespace>
          <!-- 使用新的remap语法 -->
          <remapping>~/image_raw:=/robot/camera/image_raw</remapping>
          <remapping>~/camera_info:=/robot/camera/camera_info</remapping>
        </ros>
        <camera_name>camera</camera_name>
        <frame_name>camera_optical_link</frame_name>
        <hack_baseline>0.07</hack_baseline>
      </plugin>
    </sensor>
  </gazebo>
  <link name="imu_link">
    <visual>
      <origin rpy="0 0 0" xyz="0 0 0"/>
      <geometry>
        <box size="0.04 0.03 0.01"/>
      </geometry>
      <material name="imu_material"/>
    </visual>
    <collision>
      <origin rpy="0 0 0" xyz="0 0 0"/>
      <geometry>
        <box size="0.04 0.03 0.01"/>
      </geometry>
    </collision>
    <inertial>
      <origin rpy="0 0 0" xyz="0 0 0"/>
      <mass value="0.1"/>
      <inertia ixx="8.333333333333334e-06" ixy="0" ixz="0" iyy="1.4166666666666668e-05" iyz="0" izz="2.0833333333333333e-05"/>
    </inertial>
  </link>
  <!-- IMU关节 IMU Joint - 位于车子后方上方 -->
  <joint name="imu_joint" type="fixed">
    <parent link="base_link"/>
    <child link="imu_link"/>
    <!-- 修正：相对于base_link中心，向上偏移半个chassis高度和半个imu高度 -->
    <origin rpy="0 0 0" xyz="-0.22999999999999998 0 0.065"/>
  </joint>
  <!-- Gazebo IMU插件 -->
  <gazebo reference="imu_link">
    <gravity>true</gravity>
    <sensor name="imu_sensor" type="imu">
      <always_on>true</always_on>
      <update_rate>100</update_rate>
      <visualize>true</visualize>
      <topic>__default_topic__</topic>
      <plugin filename="libgazebo_ros_imu_sensor.so" name="imu_plugin">
        <ros>
          <namespace>/robot</namespace>
          <!-- 使用新的remap语法 -->
          <remapping>~/out:=/robot/imu</remapping>
        </ros>
        <initial_orientation_as_reference>false</initial_orientation_as_reference>
      </plugin>
      <pose>0 0 0 0 0 0</pose>
    </sensor>
  </gazebo>
  <!-- Gazebo 差速驱动控制插件（只使用后轮驱动） -->
  <gazebo>
    <plugin filename="libgazebo_ros_diff_drive.so" name="differential_drive_controller">
      <ros>
        <namespace>/robot</namespace>
      </ros>
      <!-- 更新率 -->
      <update_rate>100</update_rate>
      <!-- 只使用后轮作为驱动轮 -->
      <left_joint>rear_left_wheel_joint</left_joint>
      <right_joint>rear_right_wheel_joint</right_joint>
      <!-- 运动学参数 -->
      <wheel_separation>0.46</wheel_separation>
      <wheel_diameter>0.16</wheel_diameter>
      <!-- 物理参数 -->
      <max_wheel_torque>20</max_wheel_torque>
      <max_wheel_acceleration>1.0</max_wheel_acceleration>
      <!-- 里程计配置 -->
      <publish_odom>true</publish_odom>
      <publish_odom_tf>true</publish_odom_tf>
      <publish_wheel_tf>false</publish_wheel_tf>
      <!-- 坐标系配置 -->
      <odometry_frame>odom</odometry_frame>
      <robot_base_frame>base_link</robot_base_frame>
      <!-- 话题配置 -->
      <command_topic>cmd_vel</command_topic>
      <odometry_topic>odom</odometry_topic>
    </plugin>
  </gazebo>
  <!-- Gazebo 材料属性 -->
  <gazebo reference="base_link">
    <material>Gazebo/Blue</material>
  </gazebo>
  <gazebo reference="front_left_wheel">
    <material>Gazebo/Black</material>
    <mu1>1.0</mu1>
    <mu2>1.0</mu2>
    <kp>1000000.0</kp>
    <kd>100.0</kd>
    <minDepth>0.001</minDepth>
    <maxVel>1.0</maxVel>
  </gazebo>
  <gazebo reference="front_right_wheel">
    <material>Gazebo/Black</material>
    <mu1>1.0</mu1>
    <mu2>1.0</mu2>
    <kp>1000000.0</kp>
    <kd>100.0</kd>
    <minDepth>0.001</minDepth>
    <maxVel>1.0</maxVel>
  </gazebo>
  <gazebo reference="rear_left_wheel">
    <material>Gazebo/Black</material>
    <mu1>1.0</mu1>
    <mu2>1.0</mu2>
    <kp>1000000.0</kp>
    <kd>100.0</kd>
    <minDepth>0.001</minDepth>
    <maxVel>1.0</maxVel>
  </gazebo>
  <gazebo reference="rear_right_wheel">
    <material>Gazebo/Black</material>
    <mu1>1.0</mu1>
    <mu2>1.0</mu2>
    <kp>1000000.0</kp>
    <kd>100.0</kd>
    <minDepth>0.001</minDepth>
    <maxVel>1.0</maxVel>
  </gazebo>
</robot>
